Workbook

Sheet 00 read me
A1: Sheet name | B1: Description
A2: tech-cost | B2: Annualized CAPEX and O&M costs of hydrogen production technologies
A3: FS-cost | B3: Annualized feedstock (FS) costs of hydrogen production technologies
A4: next-cost-L/M/H | B4: Synthesis costs of ammonia and methanol; methanol synthesis costs are further disaggregated into conventional CO-based routes, industrial CO₂-based routes, and DAC-derived CO₂ routes
A5: lifetime | B5: Technology lifetime
A6: OH_other | B6: National-average annual full-load hours of technologies
A7: OH_WSH | B7: Provincial annual utilization hours of hydropower, wind power, and solar PV
A8: oh_process_max | B8: Maximum annual operating hours of each process
A9: HP | B9: Efficiency of hydrogen production technologies
A10: CF | B10: Carbon emission factors of hydrogen production technologies
A11: CF_METH | B11: Carbon emission factor of methanol; as it includes downstream use-phase emissions, it is excluded from the hydrogen production emission accounting framework
A12: EXCAP | B12: Capacity trajectory of existing facilities in operation
... A33: W&S_POT | B33: Upper bounds of provincial wind and solar power potential
A35: Other descriptions
A36: Boundary of carbon emissions | B36: Covering the production, use, and end-of-life stages; the end-of-life stage specifies a fraction of carbon that can be permanently sequestered, including permanent landfilling.
A37: Boundary of CCS | B37: Excluding CCS demand associated with DACCS and end-of-life disposal.

Sheet tech-cost
A1: cost | B1: unit | C1: technology | D1: 2020 | E1: 2025 | F1: 2030 | G1: 2035 | H1: 2040 | I1: 2045 | J1: 2050 | K1: 2055 | L1: 2060
A2: CAP | B2: RMB/kW.year | C2: Wind | D2: 655.75145 | E2: 584.78359 | F2: 520.24737 | G2: 487.67244 | H2: 456.64523 | I2: 439.50857 | J2: 422.83083 | K2: 417.52758 | L2: 412.27013
A3: CAP | B3: RMB/kW.year | C3: Sloar | D3: 374.71512 | E3: 286.49077 | F3: 216.85054 | G3: 181.83093 | H3: 165.88814 | I3: 155.86542 | J3: 146.20758 | K3: 144.07872 | L3: 141.9672
A4: CAP | B4: RMB/kW.year | C4: Hydro | D4: 977.10177 | E4: 977.10177 | F4: 977.10177 | G4: 977.10177 | H4: 977.10177 | I4: 977.10177 | J4: 977.10177 | K4: 977.10177 | L4: 977.10177
A5: CAP | B5: RMB/kW.year | C5: Nuclear | D5: 1467.5528 | E5: 1341.7626 | F5: 1215.9723 | G5: 1086.3703 | H5: 1174.0423 | I5: 1153.0772 | J5: 1132.1122 | K5: 1111.1471 | L5: 1090.1821
A6: CAP | B6: RMB/kW.year | C6: Energy_stroage | D6: 745.14744 | E6: 588.32064 | F6: 497.60631 | G6: 442.82632 | H6: 383.7925 | I6: 357.82572 | J6: 333.13939 | K6: 315.3551 | L6: 326.62023
A7: CAP | B7: RMB/kW.year | C7: AE | D7: 562.07267 | E7: 471.97128 | F7: 381.86988 | G7: 354.38582 | H7: 326.90175 | I7: 313.74124 | J7: 300.58072 | K7: 297.89609 | L7: 295.21145
A8: CAP | B8: RMB/kW.year | C8: PEM | D8: 1124.1453 | E8: 821.97385 | F8: 519.80234 | G8: 444.11806 | H8: 368.43378 | I8: 337.47307 | J8: 306.51235 | K8: 291.51817 | L8: 276.524
A9: CAP | B9: RMB/kW.year | C9: SOEC | D9: 3343.1667 | E9: 1939.5812 | F9: 1180.3526 | G9: 936.78779 | H9: 740.06235 | I9: 562.07267 | J9: 487.12965 | K9: 473.07783 | L9: 459.02602
A10: CAP | B10: RMB/kW.year | C10: THP | D10: 2054.574 | E10: 1928.7837 | F10: 1802.9935 | G10: 1719.1333 | H10: 1635.2731 | I10: 1593.3431 | J10: 1551.413 | K10: 1561.8955 | L10: 1572.378
A11: CAP | B11: RMB/kW.year | C11: BG | D11: 1154.7566 | E11: 967.29614 | F11: 779.83565 | G11: 712.34987 | H11: 644.86409 | I11: 629.86725 | J11: 614.87042 | K11: 614.87042 | L11: 614.87042
A12: CAP | B12: RMB/kW.year | C12: CG | D12: 562.07267 | E12: 562.07267 | F12: 562.07267 | G12: 562.07267 | H12: 562.07267 | I12: 562.07267 | J12: 562.07267 | K12: 562.07267 | L12: 562.07267
... A27: OM | B27: RMB/kW.year | C27: EXT | D27: 102 | E27: 102 | F27: 102 | G27: 102 | H27: 102 | I27: 102 | J27: 102 | K27: 102 | L27: 102

Sheet FS-cost
A1: process | B1: unit | C1: 2020 | D1: 2025 | E1: 2030 | F1: 2035 | G1: 2040 | H1: 2045 | I1: 2050 | J1: 2055 | K1: 2060
A2: Wind-es-AE | B2: RMB/KWh | C2: 0 | D2: 0 | E2: 0 | F2: 0 | G2: 0 | H2: 0 | I2: 0 | J2: 0 | K2: 0
A3: Wind-es-PEM | B3: RMB/KWh | C3: 0 | D3: 0 | E3: 0 | F3: 0 | G3: 0 | H3: 0 | I3: 0 | J3: 0 | K3: 0
A4: Solar-es-AE | B4: RMB/KWh | C4: 0 | D4: 0 | E4: 0 | F4: 0 | G4: 0 | H4: 0 | I4: 0 | J4: 0 | K4: 0
A5: Solar-es-PEM | B5: RMB/KWh | C5: 0 | D5: 0 | E5: 0 | F5: 0 | G5: 0 | H5: 0 | I5: 0 | J5: 0 | K5: 0
A6: Hydro-es-AE | B6: RMB/KWh | C6: 0 | D6: 0 | E6: 0 | F6: 0 | G6: 0 | H6: 0 | I6: 0 | J6: 0 | K6: 0
A7: Hydro-es-PEM | B7: RMB/KWh | C7: 0 | D7: 0 | E7: 0 | F7: 0 | G7: 0 | H7: 0 | I7: 0 | J7: 0 | K7: 0
A8: Wind-wes-AE | B8: RMB/KWh | C8: 0 | D8: 0 | E8: 0 | F8: 0 | G8: 0 | H8: 0 | I8: 0 | J8: 0 | K8: 0
A9: Wind-wes-PEM | B9: RMB/KWh | C9: 0 | D9: 0 | E9: 0 | F9: 0 | G9: 0 | H9: 0 | I9: 0 | J9: 0 | K9: 0
A10: Solar-wes-AE | B10: RMB/KWh | C10: 0 | D10: 0 | E10: 0 | F10: 0 | G10: 0 | H10: 0 | I10: 0 | J10: 0 | K10: 0
A11: Solar-wes-PEM | B11: RMB/KWh | C11: 0 | D11: 0 | E11: 0 | F11: 0 | G11: 0 | H11: 0 | I11: 0 | J11: 0 | K11: 0
A12: Hydro-wes-AE | B12: RMB/KWh | C12: 0 | D12: 0 | E12: 0 | F12: 0 | G12: 0 | H12: 0 | I12: 0 | J12: 0 | K12: 0
... A26: SMR-CCS | B26: RMB/KWh | C26: 0.23225806 | D26: 0.23225806 | E26: 0.23225806 | F26: 0.27096774 | G26: 0.30967742 | H26: 0.30967742 | I26: 0.3483871 | J26: 0.3483871 | K26: 0.3483871

Sheet next-cost-L
A1: product | B1: cost | C1: unit | D1: 2020 | E1: 2025 | F1: 2030 | G1: 2035 | H1: 2040 | I1: 2045 | J1: 2050 | K1: 2055 | L1: 2060
A2: AMM | B2: CAP | C2: RMB/kgNH3 | D2: 0.775 | E2: 0.775 | F2: 0.775 | G2: 0.775 | H2: 0.775 | I2: 0.775 | J2: 0.775 | K2: 0.775 | L2: 0.775
A3: AMM | B3: OM | C3: RMB/kgNH3 | D3: 3e-06 | E3: 3e-06 | F3: 3e-06 | G3: 3e-06 | H3: 3e-06 | I3: 3e-06 | J3: 3e-06 | K3: 3e-06 | L3: 3e-06
A4: AMM | B4: FS | C4: RMB/kgNH3 | D4: 0.167862 | E4: 0.189375 | F4: 0.200586 | G4: 0.206343 | H4: 0.209979 | I4: 0.211797 | J4: 0.210888 | K4: 0.213312 | L4: 0.219675
A5: METH1 | B5: CAP | C5: RMB/kgM | D5: 0.48356 | E5: 0.48356 | F5: 0.48356 | G5: 0.48356 | H5: 0.48356 | I5: 0.48356 | J5: 0.48356 | K5: 0.48356 | L5: 0.48356
A6: METH1 | B6: OM | C6: RMB/kgM | D6: 0.193424 | E6: 0.193424 | F6: 0.193424 | G6: 0.193424 | H6: 0.193424 | I6: 0.193424 | J6: 0.193424 | K6: 0.193424 | L6: 0.193424
A7: METH1 | B7: FS | C7: RMB/kgM | D7: 0.173402 | E7: 0.195625 | F7: 0.207206 | G7: 0.213153 | H7: 0.216909 | I7: 0.218787 | J7: 0.217848 | K7: 0.220352 | L7: 0.226925
A8: METH2 | B8: CAP | C8: RMB/kgM | D8: 0.722828 | E8: 0.6324745 | F8: 0.542121 | G8: 0.47435587 | H8: 0.40659075 | I8: 0.38579537 | J8: 0.365 | K8: 0.33497153 | L8: 0.30494306
A9: METH2 | B9: OM | C9: RMB/kgM | D9: 0.24094267 | E9: 0.21082483 | F9: 0.180707 | G9: 0.15811863 | H9: 0.13553025 | I9: 0.12859846 | J9: 0.12166667 | K9: 0.11165718 | L9: 0.10164769
A10: METH2 | B10: FS | C10: RMB/kgM | D10: 0.891453 | E10: 0.87020719 | F10: 0.84032925 | G10: 0.82287956 | H10: 0.80367525 | I10: 0.78586954 | J10: 0.76604445 | K10: 0.72761422 | L10: 0.691845
A11: METH3 | B11: CAP | C11: RMB/kgM | D11: 0.722828 | E11: 0.6324745 | F11: 0.542121 | G11: 0.47435587 | H11: 0.40659075 | I11: 0.38579537 | J11: 0.365 | K11: 0.33497153 | L11: 0.30494306
A12: METH3 | B12: OM | C12: RMB/kgM | D12: 0.24094267 | E12: 0.21082483 | F12: 0.180707 | G12: 0.15811863 | H12: 0.13553025 | I12: 0.12859846 | J12: 0.12166667 | K12: 0.11165718 | L12: 0.10164769
A13: METH3 | B13: FS | C13: RMB/kgM | D13: 3.615078 | E13: 2.7518203 | F13: 2.006493 | G13: 1.9531941 | H13: 1.7747842 | I13: 1.6840333 | J13: 1.591263 | K13: 1.552176 | L13: 1.51575

Sheet next-cost-M
A1: product | B1: cost | C1: unit | D1: 2020 | E1: 2025 | F1: 2030 | G1: 2035 | H1: 2040 | I1: 2045 | J1: 2050 | K1: 2055 | L1: 2060
A2: AMM | B2: CAP | C2: RMB/kgNH3 | D2: 0.775 | E2: 0.775 | F2: 0.775 | G2: 0.775 | H2: 0.775 | I2: 0.775 | J2: 0.775 | K2: 0.775 | L2: 0.775
A3: AMM | B3: OM | C3: RMB/kgNH3 | D3: 3e-06 | E3: 3e-06 | F3: 3e-06 | G3: 3e-06 | H3: 3e-06 | I3: 3e-06 | J3: 3e-06 | K3: 3e-06 | L3: 3e-06
A4: AMM | B4: FS | C4: RMB/kgNH3 | D4: 0.167862 | E4: 0.189375 | F4: 0.200586 | G4: 0.206343 | H4: 0.209979 | I4: 0.211797 | J4: 0.210888 | K4: 0.213312 | L4: 0.219675
A5: METH1 | B5: CAP | C5: RMB/kgM | D5: 0.48356 | E5: 0.48356 | F5: 0.48356 | G5: 0.48356 | H5: 0.48356 | I5: 0.48356 | J5: 0.48356 | K5: 0.48356 | L5: 0.48356
A6: METH1 | B6: OM | C6: RMB/kgM | D6: 0.193424 | E6: 0.193424 | F6: 0.193424 | G6: 0.193424 | H6: 0.193424 | I6: 0.193424 | J6: 0.193424 | K6: 0.193424 | L6: 0.193424
A7: METH1 | B7: FS | C7: RMB/kgM | D7: 0.173402 | E7: 0.195625 | F7: 0.207206 | G7: 0.213153 | H7: 0.216909 | I7: 0.218787 | J7: 0.217848 | K7: 0.220352 | L7: 0.226925
A8: METH2 | B8: CAP | C8: RMB/kgM | D8: 0.722828 | E8: 0.6324745 | F8: 0.542121 | G8: 0.47435587 | H8: 0.40659075 | I8: 0.38579537 | J8: 0.365 | K8: 0.33497153 | L8: 0.30494306
A9: METH2 | B9: OM | C9: RMB/kgM | D9: 0.24094267 | E9: 0.21082483 | F9: 0.180707 | G9: 0.15811863 | H9: 0.13553025 | I9: 0.12859846 | J9: 0.12166667 | K9: 0.11165718 | L9: 0.10164769
A10: METH2 | B10: FS | C10: RMB/kgM | D10: 0.891453 | E10: 0.87020719 | F10: 0.84032925 | G10: 0.82287956 | H10: 0.80367525 | I10: 0.78586954 | J10: 0.76604445 | K10: 0.72761422 | L10: 0.691845
A11: METH3 | B11: CAP | C11: RMB/kgM | D11: 0.722828 | E11: 0.6324745 | F11: 0.542121 | G11: 0.47435587 | H11: 0.40659075 | I11: 0.38579537 | J11: 0.365 | K11: 0.33497153 | L11: 0.30494306
A12: METH3 | B12: OM | C12: RMB/kgM | D12: 0.24094267 | E12: 0.21082483 | F12: 0.180707 | G12: 0.15811863 | H12: 0.13553025 | I12: 0.12859846 | J12: 0.12166667 | K12: 0.11165718 | L12: 0.10164769
A13: METH3 | B13: FS | C13: RMB/kgM | D13: 3.615078 | E13: 3.1234922 | F13: 2.6232743 | G13: 2.4020691 | H13: 2.1791093 | I13: 2.0660833 | J13: 1.951038 | K13: 1.902501 | L13: 1.856625

Sheet next-cost-H
A1: product | B1: cost | C1: unit | D1: 2020 | E1: 2025 | F1: 2030 | G1: 2035 | H1: 2040 | I1: 2045 | J1: 2050 | K1: 2055 | L1: 2060
A2: AMM | B2: CAP | C2: RMB/kgNH3 | D2: 0.775 | E2: 0.775 | F2: 0.775 | G2: 0.775 | H2: 0.775 | I2: 0.775 | J2: 0.775 | K2: 0.775 | L2: 0.775
A3: AMM | B3: OM | C3: RMB/kgNH3 | D3: 3e-06 | E3: 3e-06 | F3: 3e-06 | G3: 3e-06 | H3: 3e-06 | I3: 3e-06 | J3: 3e-06 | K3: 3e-06 | L3: 3e-06
A4: AMM | B4: FS | C4: RMB/kgNH3 | D4: 0.167862 | E4: 0.189375 | F4: 0.200586 | G4: 0.206343 | H4: 0.209979 | I4: 0.211797 | J4: 0.210888 | K4: 0.213312 | L4: 0.219675
A5: METH1 | B5: CAP | C5: RMB/kgM | D5: 0.48356 | E5: 0.48356 | F5: 0.48356 | G5: 0.48356 | H5: 0.48356 | I5: 0.48356 | J5: 0.48356 | K5: 0.48356 | L5: 0.48356
A6: METH1 | B6: OM | C6: RMB/kgM | D6: 0.193424 | E6: 0.193424 | F6: 0.193424 | G6: 0.193424 | H6: 0.193424 | I6: 0.193424 | J6: 0.193424 | K6: 0.193424 | L6: 0.193424
A7: METH1 | B7: FS | C7: RMB/kgM | D7: 0.173402 | E7: 0.195625 | F7: 0.207206 | G7: 0.213153 | H7: 0.216909 | I7: 0.218787 | J7: 0.217848 | K7: 0.220352 | L7: 0.226925
A8: METH2 | B8: CAP | C8: RMB/kgM | D8: 0.722828 | E8: 0.6324745 | F8: 0.542121 | G8: 0.47435587 | H8: 0.40659075 | I8: 0.38579537 | J8: 0.365 | K8: 0.33497153 | L8: 0.30494306
A9: METH2 | B9: OM | C9: RMB/kgM | D9: 0.24094267 | E9: 0.21082483 | F9: 0.180707 | G9: 0.15811863 | H9: 0.13553025 | I9: 0.12859846 | J9: 0.12166667 | K9: 0.11165718 | L9: 0.10164769
A10: METH2 | B10: FS | C10: RMB/kgM | D10: 0.891453 | E10: 0.87020719 | F10: 0.84032925 | G10: 0.82287956 | H10: 0.80367525 | I10: 0.78586954 | J10: 0.76604445 | K10: 0.72761422 | L10: 0.691845
A11: METH3 | B11: CAP | C11: RMB/kgM | D11: 0.722828 | E11: 0.6324745 | F11: 0.542121 | G11: 0.47435587 | H11: 0.40659075 | I11: 0.38579537 | J11: 0.365 | K11: 0.33497153 | L11: 0.30494306
A12: METH3 | B12: OM | C12: RMB/kgM | D12: 0.24094267 | E12: 0.21082483 | F12: 0.180707 | G12: 0.15811863 | H12: 0.13553025 | I12: 0.12859846 | J12: 0.12166667 | K12: 0.11165718 | L12: 0.10164769
A13: METH3 | B13: FS | C13: RMB/kgM | D13: 3.615078 | E13: 3.4951641 | F13: 3.2400555 | G13: 2.8509441 | H13: 2.5834342 | I13: 2.4481333 | J13: 2.310813 | K13: 2.252826 | L13: 2.1975

Sheet lifetime
A1: technology | B1: unit | C1: 2020 | D1: 2030 | E1: 2040 | F1: 2050 | G1: 2060
A2: Wind | B2: year | C2: 25 | D2: 25 | E2: 25 | F2: 25 | G2: 25
A3: Sloar | B3: year | C3: 25 | D3: 25 | E3: 25 | F3: 25 | G3: 25
A4: Hydro | B4: year | C4: 30 | D4: 30 | E4: 30 | F4: 30 | G4: 30
A5: Nuclear | B5: year | C5: 40 | D5: 40 | E5: 40 | F5: 40 | G5: 40
A6: Energy_stroage | B6: year | C6: 5 | D6: 6 | E6: 7 | F6: 8 | G6: 9
A7: AE | B7: year | C7: =IF(C24/C27>20,20,C24/C27) -> 12.5 | D7: =IF(D24/D27>20,20,D24/D27) -> 12.5 | E7: =IF(E24/E27>20,20,E24/E27) -> 12.5 | F7: =IF(F24/F27>20,20,F24/F27) -> 12.5 | G7: =IF(G24/G27>20,20,G24/G27) -> 12.5
A8: PEM | B8: year | C8: 7.5 | D8: 7.8 | E8: 8.1 | F8: 8.25 | G8: 8.33
A9: SOEC | B9: year | C9: 3.33 | D9: 5 | E9: 5.83 | F9: 6.4 | G9: 6.6
A10: THP | B10: year | C10: 40 | D10: 40 | E10: 40 | F10: 40 | G10: 40
A11: BG | B11: year | C11: 30 | D11: 30 | E11: 30 | F11: 30 | G11: 30
A12: CG | B12: year | C12: 25 | D12: 25 | E12: 25 | F12: 25 | G12: 25
A13: SMR | B13: year | C13: 25 | D13: 25 | E13: 25 | F13: 25 | G13: 25
A14: EXT | B14: year | C14: 10 | D14: 10 | E14: 10 | F14: 10 | G14: 10
A15: ETH-NSC | B15: year | C15: 25 | D15: 25 | E15: 25 | F15: 25 | G15: 25
A16: PRO-NSC | B16: year | C16: 25 | D16: 25 | E16: 25 | F16: 25 | G16: 25
A17: BTX-NSC | B17: year | C17: 25 | D17: 25 | E17: 25 | F17: 25 | G17: 25
A18: ETH-ESC | B18: year | C18: 25 | D18: 25 | E18: 25 | F18: 25 | G18: 25
A19: BTX-CR | B19: year | C19: 25 | D19: 25 | E19: 25 | F19: 25 | G19: 25
... A29: SOEC-OPH | B29: h | C29: 6000 | D29: 6000 | E29: 6000 | F29: 6000 | G29: 6000

Sheet OH_other
A1: technology | B1: unit | C1: 2020 | D1: 2030 | E1: 2040 | F1: 2050 | G1: 2060
A2: Wind | B2: h | C2: 2200 | D2: 2250 | E2: 2300 | F2: 2350 | G2: 2400
A3: Sloar | B3: h | C3: 1300 | D3: 1350 | E3: 1400 | F3: 1450 | G3: 1500
A4: Hydro | B4: h | C4: 3800 | D4: 3800 | E4: 3800 | F4: 3800 | G4: 3800
A5: Nuclear | B5: h | C5: 7500 | D5: 7500 | E5: 7500 | F5: 7500 | G5: 7500
A6: Energy_stroage | B6: h | C6: 2500 | D6: 2500 | E6: 2500 | F6: 2500 | G6: 2500
A7: AE | B7: h | C7: 5000 | D7: 5000 | E7: 5000 | F7: 5000 | G7: 5000
A8: PEM | B8: h | C8: 5000 | D8: 5000 | E8: 5000 | F8: 5000 | G8: 5000
A9: SOEC | B9: h | C9: 5000 | D9: 5000 | E9: 5000 | F9: 5000 | G9: 5000
A10: THP | B10: h | C10: 7500 | D10: 7500 | E10: 7500 | F10: 7500 | G10: 7500
A11: BG | B11: h | C11: 6500 | D11: 6500 | E11: 6500 | F11: 6500 | G11: 6500
A12: CG | B12: h | C12: 7500 | D12: 7500 | E12: 7500 | F12: 7500 | G12: 7500
... A14: EXT | B14: h | C14: 8000 | D14: 8000 | E14: 8000 | F14: 8000 | G14: 8000

Sheet OH_WSH
A1: PROVINCE_ID | B1: PROVINCE | C1: Hydro-OH | D1: Wind-OH | E1: Solar-OH
A2: AH | B2: Anhui | C2: 1838.7097 | D2: 2032.5203 | E2: 698.1982
A3: BJ | B3: Beijing | C3: 1122.449 | D3: 1578.9474 | E3: 800
A4: CQ | B4: Chongqing | C4: 3437.5 | D4: 1600 | E4: 166.66667
A5: FJ | B5: Fujian | C5: 3182.8615 | D5: 2400 | E5: 652.17391
A6: GS | B6: Gansu | C6: 4308.7558 | D6: 2215.2886 | E6: 1164.1221
A7: GD | B7: Guangdong | C7: 2025.572 | D7: 1764.7059 | E7: 602.40964
A8: GX | B8: Guangxi | C8: 3798.6818 | D8: 2019.2308 | E8: 525.64103
A9: GZ | B9: Guizhou | C9: 3459.1789 | D9: 1782.3834 | E9: 422.22222
A10: HI | B10: Hainan | C10: 2280.7018 | D10: 1470.5882 | E10: 697.67442
A11: HE | B11: Hebei | C11: 1098.9011 | D11: 2145.9382 | E11: 905.52995
A12: HL | B12: Heilongjiang | C12: 2427.1845 | D12: 2187.291 | E12: 606.38298
A13: HA | B13: Henan | C13: 2506.2657 | D13: 1217.9487 | E13: 625.88905
... A31: ZJ | B31: Zhejiang | C31: 1827.5862 | D31: 2094.5946 | E31: 687.96069

Sheet oh_process_max
A1: process | B1: unit | C1: 2020 | D1: 2030 | E1: 2040 | F1: 2050 | G1: 2060
A2: Wind-es-AE | B2: h/year | C2: =5000-C11 -> 2800 | D2: =5000-D11 -> 2750 | E2: =5000-E11 -> 2700 | F2: =5000-F11 -> 2650 | G2: =5000-G11 -> 2600
A3: Wind-es-PEM | B3: h/year | C3: =5000-C12 -> 2800 | D3: =5000-D12 -> 2750 | E3: =5000-E12 -> 2700 | F3: =5000-F12 -> 2650 | G3: =5000-G12 -> 2600
A4: Solar-es-AE | B4: h/year | C4: =5000-C13 -> 3700 | D4: =5000-D13 -> 3650 | E4: =5000-E13 -> 3600 | F4: =5000-F13 -> 3550 | G4: =5000-G13 -> 3500
A5: Solar-es-PEM | B5: h/year | C5: =5000-C14 -> 3700 | D5: =5000-D14 -> 3650 | E5: =5000-E14 -> 3600 | F5: =5000-F14 -> 3550 | G5: =5000-G14 -> 3500
A6: Hydro-es-AE | B6: h/year | C6: =5000-C15 -> 1200 | D6: =5000-D15 -> 1200 | E6: =5000-E15 -> 1200 | F6: =5000-F15 -> 1200 | G6: =5000-G15 -> 1200
A7: Hydro-es-PEM | B7: h/year | C7: =5000-C16 -> 1200 | D7: =5000-D16 -> 1200 | E7: =5000-E16 -> 1200 | F7: =5000-F16 -> 1200 | G7: =5000-G16 -> 1200
A8: Nuclear-es-AE | B8: h/year | C8: =7500-C17 -> 2500 | D8: =7500-D17 -> 2500 | E8: =7500-E17 -> 2500 | F8: =7500-F17 -> 2500 | G8: =7500-G17 -> 2500
A9: Nuclear-es-PEM | B9: h/year | C9: =7500-C18 -> 2500 | D9: =7500-D18 -> 2500 | E9: =7500-E18 -> 2500 | F9: =7500-F18 -> 2500 | G9: =7500-G18 -> 2500
A10: Nuclear-es-SOEC | B10: h/year | C10: =7500-C19 -> 2500 | D10: =7500-D19 -> 2500 | E10: =7500-E19 -> 2500 | F10: =7500-F19 -> 2500 | G10: =7500-G19 -> 2500
A11: Wind-wes-AE | B11: h/year | C11: =OH_other!C2 -> 2200 | D11: =OH_other!D2 -> 2250 | E11: =OH_other!E2 -> 2300 | F11: =OH_other!F2 -> 2350 | G11: =OH_other!G2 -> 2400
A12: Wind-wes-PEM | B12: h/year | C12: =OH_other!C2 -> 2200 | D12: =OH_other!D2 -> 2250 | E12: =OH_other!E2 -> 2300 | F12: =OH_other!F2 -> 2350 | G12: =OH_other!G2 -> 2400
A13: Solar-wes-AE | B13: h/year | C13: =OH_other!C3 -> 1300 | D13: =OH_other!D3 -> 1350 | E13: =OH_other!E3 -> 1400 | F13: =OH_other!F3 -> 1450 | G13: =OH_other!G3 -> 1500
A14: Solar-wes-PEM | B14: h/year | C14: =OH_other!C3 -> 1300 | D14: =OH_other!D3 -> 1350 | E14: =OH_other!E3 -> 1400 | F14: =OH_other!F3 -> 1450 | G14: =OH_other!G3 -> 1500
A15: Hydro-wes-AE | B15: h/year | C15: =OH_other!C4 -> 3800 | D15: =OH_other!D4 -> 3800 | E15: =OH_other!E4 -> 3800 | F15: =OH_other!F4 -> 3800 | G15: =OH_other!G4 -> 3800
A16: Hydro-wes-PEM | B16: h/year | C16: =OH_other!C4 -> 3800 | D16: =OH_other!D4 -> 3800 | E16: =OH_other!E4 -> 3800 | F16: =OH_other!F4 -> 3800 | G16: =OH_other!G4 -> 3800
A17: Nuclear-wes-AE | B17: h/year | C17: =OH_other!C9 -> 5000 | D17: =OH_other!D9 -> 5000 | E17: =OH_other!E9 -> 5000 | F17: =OH_other!F9 -> 5000 | G17: =OH_other!G9 -> 5000
A18: Nuclear-wes-PEM | B18: h/year | C18: =OH_other!C8 -> 5000 | D18: =OH_other!D8 -> 5000 | E18: =OH_other!E8 -> 5000 | F18: =OH_other!F8 -> 5000 | G18: =OH_other!G8 -> 5000
A19: Nuclear-wes-SOEC | B19: h/year | C19: =OH_other!C9 -> 5000 | D19: =OH_other!D9 -> 5000 | E19: =OH_other!E9 -> 5000 | F19: =OH_other!F9 -> 5000 | G19: =OH_other!G9 -> 5000
A20: Grid-AE | B20: h/year | C20: =OH_other!C7 -> 5000 | D20: =OH_other!D7 -> 5000 | E20: =OH_other!E7 -> 5000 | F20: =OH_other!F7 -> 5000 | G20: =OH_other!G7 -> 5000
A21: Grid-PEM | B21: h/year | C21: =OH_other!C8 -> 5000 | D21: =OH_other!D8 -> 5000 | E21: =OH_other!E8 -> 5000 | F21: =OH_other!F8 -> 5000 | G21: =OH_other!G8 -> 5000
A22: Nuclear-THP | B22: h/year | C22: =OH_other!C10 -> 7500 | D22: =OH_other!D10 -> 7500 | E22: =OH_other!E10 -> 7500 | F22: =OH_other!F10 -> 7500 | G22: =OH_other!G10 -> 7500
A23: BG | B23: h/year | C23: =OH_other!C11 -> 6500 | D23: =OH_other!D11 -> 6500 | E23: =OH_other!E11 -> 6500 | F23: =OH_other!F11 -> 6500 | G23: =OH_other!G11 -> 6500
A24: CG | B24: h/year | C24: =OH_other!C12 -> 7500 | D24: =OH_other!D12 -> 7500 | E24: =OH_other!E12 -> 7500 | F24: =OH_other!F12 -> 7500 | G24: =OH_other!G12 -> 7500
A25: SMR | B25: h/year | C25: =OH_other!C13 -> 7500 | D25: =OH_other!D13 -> 7500 | E25: =OH_other!E13 -> 7500 | F25: =OH_other!F13 -> 7500 | G25: =OH_other!G13 -> 7500
A26: EXT | B26: h/year | C26: =OH_other!C14 -> 8000 | D26: =OH_other!D14 -> 8000 | E26: =OH_other!E14 -> 8000 | F26: =OH_other!F14 -> 8000 | G26: =OH_other!G14 -> 8000
A27: BG-CCS | B27: h/year | C27: =C23 -> 6500 | D27: =D23 -> 6500 | E27: =E23 -> 6500 | F27: =F23 -> 6500 | G27: =G23 -> 6500
A28: CG-CCS | B28: h/year | C28: =C24 -> 7500 | D28: =D24 -> 7500 | E28: =E24 -> 7500 | F28: =F24 -> 7500 | G28: =G24 -> 7500
A29: SMR-CCS | B29: h/year | C29: =C25 -> 7500 | D29: =D25 -> 7500 | E29: =E25 -> 7500 | F29: =F25 -> 7500 | G29: =G25 -> 7500

Sheet HP
A1: process | B1: unit | C1: 2020 | D1: 2025 | E1: 2030 | F1: 2035 | G1: 2040 | H1: 2045 | I1: 2050 | J1: 2055 | K1: 2060
A2: Wind-es-AE | B2: kg/kWh | C2: 0.016575 | D2: 0.017258625 | E2: 0.017854875 | F2: 0.01846125 | G2: 0.0189735 | H2: 0.019386562 | I2: 0.019803 | J2: 0.020222812 | K2: 0.020646
A3: Wind-es-PEM | B3: kg/kWh | C3: 0.01785 | D3: 0.01859625 | E3: 0.01924875 | F3: 0.0199125 | G3: 0.020475 | H3: 0.020930625 | I3: 0.02139 | J3: 0.021853125 | K3: 0.02232
A4: Solar-es-AE | B4: kg/kWh | C4: 0.016575 | D4: 0.017258625 | E4: 0.017854875 | F4: 0.01846125 | G4: 0.0189735 | H4: 0.019386562 | I4: 0.019803 | J4: 0.020222812 | K4: 0.020646
A5: Solar-es-PEM | B5: kg/kWh | C5: 0.01785 | D5: 0.01859625 | E5: 0.01924875 | F5: 0.0199125 | G5: 0.020475 | H5: 0.020930625 | I5: 0.02139 | J5: 0.021853125 | K5: 0.02232
A6: Hydro-es-AE | B6: kg/kWh | C6: 0.016575 | D6: 0.017258625 | E6: 0.017854875 | F6: 0.01846125 | G6: 0.0189735 | H6: 0.019386562 | I6: 0.019803 | J6: 0.020222812 | K6: 0.020646
A7: Hydro-es-PEM | B7: kg/kWh | C7: 0.01785 | D7: 0.01859625 | E7: 0.01924875 | F7: 0.0199125 | G7: 0.020475 | H7: 0.020930625 | I7: 0.02139 | J7: 0.021853125 | K7: 0.02232
A8: Wind-wes-AE | B8: kg/kWh | C8: 0.0195 | D8: 0.0198375 | E8: 0.020175 | F8: 0.0205125 | G8: 0.02085 | H8: 0.0211875 | I8: 0.021525 | J8: 0.0218625 | K8: 0.0222
A9: Wind-wes-PEM | B9: kg/kWh | C9: 0.021 | D9: 0.021375 | E9: 0.02175 | F9: 0.022125 | G9: 0.0225 | H9: 0.022875 | I9: 0.02325 | J9: 0.023625 | K9: 0.024
A10: Solar-wes-AE | B10: kg/kWh | C10: 0.0195 | D10: 0.0198375 | E10: 0.020175 | F10: 0.0205125 | G10: 0.02085 | H10: 0.0211875 | I10: 0.021525 | J10: 0.0218625 | K10: 0.0222
A11: Solar-wes-PEM | B11: kg/kWh | C11: 0.021 | D11: 0.021375 | E11: 0.02175 | F11: 0.022125 | G11: 0.0225 | H11: 0.022875 | I11: 0.02325 | J11: 0.023625 | K11: 0.024
A12: Hydro-wes-AE | B12: kg/kWh | C12: 0.0195 | D12: 0.0198375 | E12: 0.020175 | F12: 0.0205125 | G12: 0.02085 | H12: 0.0211875 | I12: 0.021525 | J12: 0.0218625 | K12: 0.0222
... A23: EXT | B23: kg/kWh | C23: 0.03 | D23: 0.03 | E23: 0.03 | F23: 0.03 | G23: 0.03 | H23: 0.03 | I23: 0.03 | J23: 0.03 | K23: 0.03
A24: BG-CCS | B24: kg/kWh | C24: =C20*0.95 -> 0.01368 | D24: =D20*0.95 -> 0.01389375 | E24: =E20*0.95 -> 0.0141075 | F24: =F20*0.95 -> 0.01432125 | G24: =G20*0.95 -> 0.014535 | H24: =H20*0.95 -> 0.01474875 | I24: =I20*0.95 -> 0.0149625 | J24: =J20*0.95 -> 0.01517625 | K24: =K20*0.95 -> 0.01539
A25: CG-CCS | B25: kg/kWh | C25: =C21*0.95 -> 0.0171 | D25: =D21*0.95 -> 0.0171 | E25: =E21*0.95 -> 0.0171 | F25: =F21*0.95 -> 0.0171 | G25: =G21*0.95 -> 0.0171 | H25: =H21*0.95 -> 0.0171 | I25: =I21*0.95 -> 0.0171 | J25: =J21*0.95 -> 0.0171 | K25: =K21*0.95 -> 0.0171
A26: SMR-CCS | B26: kg/kWh | C26: =C22*0.95 -> 0.020800526 | D26: =D22*0.95 -> 0.020800526 | E26: =E22*0.95 -> 0.020800526 | F26: =F22*0.95 -> 0.020800526 | G26: =G22*0.95 -> 0.020800526 | H26: =H22*0.95 -> 0.020800526 | I26: =I22*0.95 -> 0.020800526 | J26: =J22*0.95 -> 0.020800526 | K26: =K22*0.95 -> 0.020800526
A27: es_effiency | B27: % | C27: 85 | D27: 87 | E27: 88.5 | F27: 90 | G27: 91 | H27: 91.5 | I27: 92 | J27: 92.5 | K27: 93

Sheet CF
A1: process | B1: unit | C1: 2020 | D1: 2025 | E1: 2030 | F1: 2035 | G1: 2040 | H1: 2045 | I1: 2050 | J1: 2055 | K1: 2060
A2: Wind-es-AE | B2: kgCO2/kgH2 | C2: 0 | D2: 0 | E2: 0 | F2: 0 | G2: 0 | H2: 0 | I2: 0 | J2: 0 | K2: 0
A3: Wind-es-PEM | B3: kgCO2/kgH2 | C3: 0 | D3: 0 | E3: 0 | F3: 0 | G3: 0 | H3: 0 | I3: 0 | J3: 0 | K3: 0
A4: Solar-es-AE | B4: kgCO2/kgH2 | C4: 0 | D4: 0 | E4: 0 | F4: 0 | G4: 0 | H4: 0 | I4: 0 | J4: 0 | K4: 0
A5: Solar-es-PEM | B5: kgCO2/kgH2 | C5: 0 | D5: 0 | E5: 0 | F5: 0 | G5: 0 | H5: 0 | I5: 0 | J5: 0 | K5: 0
A6: Hydro-es-AE | B6: kgCO2/kgH2 | C6: 0 | D6: 0 | E6: 0 | F6: 0 | G6: 0 | H6: 0 | I6: 0 | J6: 0 | K6: 0
A7: Hydro-es-PEM | B7: kgCO2/kgH2 | C7: 0 | D7: 0 | E7: 0 | F7: 0 | G7: 0 | H7: 0 | I7: 0 | J7: 0 | K7: 0
A8: Wind-wes-AE | B8: kgCO2/kgH2 | C8: 0 | D8: 0 | E8: 0 | F8: 0 | G8: 0 | H8: 0 | I8: 0 | J8: 0 | K8: 0
A9: Wind-wes-PEM | B9: kgCO2/kgH2 | C9: 0 | D9: 0 | E9: 0 | F9: 0 | G9: 0 | H9: 0 | I9: 0 | J9: 0 | K9: 0
A10: Solar-wes-AE | B10: kgCO2/kgH2 | C10: 0 | D10: 0 | E10: 0 | F10: 0 | G10: 0 | H10: 0 | I10: 0 | J10: 0 | K10: 0
A11: Solar-wes-PEM | B11: kgCO2/kgH2 | C11: 0 | D11: 0 | E11: 0 | F11: 0 | G11: 0 | H11: 0 | I11: 0 | J11: 0 | K11: 0
A12: Hydro-wes-AE | B12: kgCO2/kgH2 | C12: 0 | D12: 0 | E12: 0 | F12: 0 | G12: 0 | H12: 0 | I12: 0 | J12: 0 | K12: 0
... A26: SMR-CCS | B26: kgCO2/kgH2 | C26: 1.05 | D26: 1.05 | E26: 1.05 | F26: 1.05 | G26: 1.05 | H26: 1.05 | I26: 1.05 | J26: 1.05 | K26: 1.05

Sheet CF_METH
A1: process | B1: unit | C1: 2020 | D1: 2025 | E1: 2030 | F1: 2035 | G1: 2040 | H1: 2045 | I1: 2050 | J1: 2055 | K1: 2060
A2: Coal-based | B2: tCO2/tMETH | C2: 3.575 | D2: 3.575 | E2: 3.575 | F2: 3.575 | G2: 3.575 | H2: 3.575 | I2: 3.575 | J2: 3.575 | K2: 3.575
A3: Coal-based-CCS | B3: tCO2/tMETH | C3: 1.44375 | D3: 1.44375 | E3: 1.44375 | F3: 1.44375 | G3: 1.44375 | H3: 1.44375 | I3: 1.44375 | J3: 1.44375 | K3: 1.44375
A4: Gas-based | B4: tCO2/tMETH | C4: 1.48 | D4: 1.48 | E4: 1.48 | F4: 1.48 | G4: 1.48 | H4: 1.48 | I4: 1.48 | J4: 1.48 | K4: 1.48
A5: Gas-based-CCS | B5: tCO2/tMETH | C5: 1.4 | D5: 1.4 | E5: 1.4 | F5: 1.4 | G5: 1.4 | H5: 1.4 | I5: 1.4 | J5: 1.4 | K5: 1.4
A6: By-product-based | B6: tCO2/tMETH | C6: 0 | D6: 0 | E6: 0 | F6: 0 | G6: 0 | H6: 0 | I6: 0 | J6: 0 | K6: 0
A7: Coal-GH-based | B7: tCO2/tMETH | C7: 1.375 | D7: 1.375 | E7: 1.375 | F7: 1.375 | G7: 1.375 | H7: 1.375 | I7: 1.375 | J7: 1.375 | K7: 1.375
A8: Biomass-based | B8: tCO2/tMETH | C8: 0 | D8: 0 | E8: 0 | F8: 0 | G8: 0 | H8: 0 | I8: 0 | J8: 0 | K8: 0
A9: Biomass-based-CCS | B9: tCO2/tMETH | C9: -0.9 | D9: -0.9 | E9: -0.9 | F9: -0.9 | G9: -0.9 | H9: -0.9 | I9: -0.9 | J9: -0.9 | K9: -0.9
A10: CO2-GH-based | B10: tCO2/tMETH | C10: 0 | D10: 0 | E10: 0 | F10: 0 | G10: 0 | H10: 0 | I10: 0 | J10: 0 | K10: 0
A11: DAC-GH-based | B11: tCO2/tMETH | C11: 0 | D11: 0 | E11: 0 | F11: 0 | G11: 0 | H11: 0 | I11: 0 | J11: 0 | K11: 0

Sheet EXCAP
A1: technology | B1: unit | C1: 2020 | D1: 2025 | E1: 2030 | F1: 2035 | G1: 2040 | H1: 2045 | I1: 2050 | J1: 2055 | K1: 2060
A2: Wind | B2: KW | C2: 0 | D2: 0 | E2: 0 | F2: 0 | G2: 0 | H2: 0 | I2: 0 | J2: 0 | K2: 0
A3: Sloar | B3: KW | C3: 0 | D3: 0 | E3: 0 | F3: 0 | G3: 0 | H3: 0 | I3: 0 | J3: 0 | K3: 0
A4: Hydro | B4: KW | C4: 0 | D4: 0 | E4: 0 | F4: 0 | G4: 0 | H4: 0 | I4: 0 | J4: 0 | K4: 0
A5: Nuclear | B5: KW | C5: 0 | D5: 0 | E5: 0 | F5: 0 | G5: 0 | H5: 0 | I5: 0 | J5: 0 | K5: 0
A6: Energy_stroage | B6: KW | C6: 0 | D6: 0 | E6: 0 | F6: 0 | G6: 0 | H6: 0 | I6: 0 | J6: 0 | K6: 0
A7: AE | B7: KW | C7: 0 | D7: 0 | E7: 0 | F7: 0 | G7: 0 | H7: 0 | I7: 0 | J7: 0 | K7: 0
A8: PEM | B8: KW | C8: 0 | D8: 0 | E8: 0 | F8: 0 | G8: 0 | H8: 0 | I8: 0 | J8: 0 | K8: 0
A9: SOEC | B9: KW | C9: 0 | D9: 0 | E9: 0 | F9: 0 | G9: 0 | H9: 0 | I9: 0 | J9: 0 | K9: 0
A10: THP | B10: KW | C10: 0 | D10: 0 | E10: 0 | F10: 0 | G10: 0 | H10: 0 | I10: 0 | J10: 0 | K10: 0
A11: BG | B11: KW | C11: 0 | D11: 0 | E11: 0 | F11: 0 | G11: 0 | H11: 0 | I11: 0 | J11: 0 | K11: 0
A12: CG | B12: KW | C12: =((SUM('H2_P&C'!B2:B5)*10000000*(1.6/1.3))*(2/1.6))/2 -> 1.5570846e+08 | D12: =0.5*C12+0.5*E12 -> 1.2273434e+08 | E12: 89760219 | F12: =0.5*G12+0.5*E12 -> 49840146 | G12: 9920073.1 | H12: 0 | I12: 0 | J12: 0 | K12: 0
A13: SMR | B13: KW | C13: =((SUM('H2_P&C'!C2:C5)*10000000*(1.6/1.3))*(2/1.6))/2 -> 62332056 | D13: =0.5*C13+0.5*E13 -> 56193400 | E13: 50054745 | F13: =0.5*G13+0.5*E13 -> 29536497 | G13: 9018248.3 | H13: 0 | I13: 0 | J13: 0 | K13: 0
A14: EXT | B14: KW | C14: =((SUM('H2_P&C'!D2:D5)*10000000*(1.6/1.3))*(2/1.6))/2 -> 49618056 | D14: =0.5*C14+0.5*E14 -> 40678346 | E14: 31738636 | F14: 14053977 | G14: 5769318.2 | H14: 0 | I14: 0 | J14: 0 | K14: 0
A15: ETH-NSC | B15: Mt | C15: =SUM(province_structure!K2:K31)/0.8 -> 25.487946 | D15: =C15*0.5+E15*0.5 -> 20.390357 | E15: =C15*0.6 -> 15.292768 | F15: =E15*0.5+G15*0.5 -> 9.5579799 | G15: =E15*0.25 -> 3.8231919 | H15: 0 | I15: 0 | J15: 0 | K15: 0
A16: PRO-NSC | B16: Mt | C16: =SUM(province_structure!O2:O31)/0.8 -> 14.076418 | D16: =C16*0.5+E16*0.5 -> 11.261134 | E16: =C16*0.6 -> 8.4458506 | F16: =E16*0.5+G16*0.5 -> 5.2786566 | G16: =E16*0.25 -> 2.1114627 | H16: 0 | I16: 0 | J16: 0 | K16: 0
A17: BTX-NSC | B17: Mt | C17: =SUM(province_structure!Q2:Q31)/0.8 -> 16.873504 | D17: =C17*0.5+E17*0.5 -> 13.498804 | E17: =C17*0.6 -> 10.124103 | F17: =E17*0.5+G17*0.5 -> 6.3275641 | G17: =E17*0.25 -> 2.5310257 | H17: 0 | I17: 0 | J17: 0 | K17: 0
A18: ETH-ESC | B18: Mt | C18: =SUM(province_structure!K2:K31)/0.85 -> 23.988655 | D18: =C18*0.5+E18*0.5 -> 19.190924 | E18: =C18*0.6 -> 14.393193 | F18: =E18*0.5+G18*0.5 -> 8.9957457 | G18: =E18*0.25 -> 3.5982983 | H18: 0 | I18: 0 | J18: 0 | K18: 0
A19: BTX-CR | B19: Mt | C19: =SUM(province_structure!P2:P31)/0.85 -> 47.734442 | D19: =C19*0.5+E19*0.5 -> 38.187553 | E19: =C19*0.6 -> 28.640665 | F19: =E19*0.5+G19*0.5 -> 17.900416 | G19: =E19*0.25 -> 7.1601662 | H19: 0 | I19: 0 | J19: 0 | K19: 0
A20: PRO-CC | B20: Mt | C20: =SUM(province_structure!N2:N31)/0.85 -> 6.4943176 | D20: =C20*0.5+E20*0.5 -> 5.1954541 | E20: =C20*0.6 -> 3.8965906 | F20: =E20*0.5+G20*0.5 -> 2.4353691 | G20: =E20*0.25 -> 0.97414764 | H20: 0 | I20: 0 | J20: 0 | K20: 0
A21: PRO-PDH | B21: Mt | C21: =SUM(province_structure!M2:M31)/0.85 -> 17.204647 | D21: =C21*0.5+E21*0.5 -> 13.763718 | E21: =C21*0.6 -> 10.322788 | F21: =E21*0.5+G21*0.5 -> 6.4517428 | G21: =E21*0.25 -> 2.5806971 | H21: 0 | I21: 0 | J21: 0 | K21: 0
A22: ETH-MTO | B22: Mt | C22: =SUM(province_structure!I2:I31)/0.85 -> 4.4237972 | D22: =C22*0.5+E22*0.5 -> 3.5390378 | E22: =C22*0.6 -> 2.6542783 | F22: =E22*0.5+G22*0.5 -> 1.658924 | G22: =E22*0.25 -> 0.66356958 | H22: 0 | I22: 0 | J22: 0 | K22: 0
A23: PRO-MTO | B23: Mt | C23: =SUM(province_structure!L2:L31)/0.85 -> 10.884012 | D23: =C23*0.5+E23*0.5 -> 8.7072093 | E23: =C23*0.6 -> 6.530407 | F23: =E23*0.5+G23*0.5 -> 4.0815044 | G23: =E23*0.25 -> 1.6326017 | H23: 0 | I23: 0 | J23: 0 | K23: 0

Sheet POT
A1: technologies | B1: unit | C1: 2020 | D1: 2025 | E1: 2030 | F1: 2035 | G1: 2040 | H1: 2045 | I1: 2050 | J1: 2055 | K1: 2060
A2: Wind | B2: KW | C2: 1e+27 | D2: 1e+27 | E2: 1e+27 | F2: 1e+27 | G2: 1e+27 | H2: 1e+27 | I2: 1e+27 | J2: 1e+27 | K2: 1e+27
A3: Sloar | B3: KW | C3: 1e+27 | D3: 1e+27 | E3: 1e+27 | F3: 1e+27 | G3: 1e+27 | H3: 1e+27 | I3: 1e+27 | J3: 1e+27 | K3: 1e+27
A4: Hydro | B4: KW | C4: 100000000 | D4: 100000000 | E4: 100000000 | F4: 100000000 | G4: 100000000 | H4: 100000000 | I4: 100000000 | J4: 100000000 | K4: 100000000
A5: Nuclear | B5: % | C5: 100 | D5: 100 | E5: 100 | F5: 100 | G5: 100 | H5: 100 | I5: 100 | J5: 100 | K5: 100
A6: Energy_stroage | B6: KW | C6: 1e+27 | D6: 1e+27 | E6: 1e+27 | F6: 1e+27 | G6: 1e+27 | H6: 1e+27 | I6: 1e+27 | J6: 1e+27 | K6: 1e+27
A7: AE | B7: KW | C7: 1e+27 | D7: 1e+27 | E7: 1e+27 | F7: 1e+27 | G7: 1e+27 | H7: 1e+27 | I7: 1e+27 | J7: 1e+27 | K7: 1e+27
A8: PEM | B8: KW | C8: 1e+27 | D8: 1e+27 | E8: 1e+27 | F8: 1e+27 | G8: 1e+27 | H8: 1e+27 | I8: 1e+27 | J8: 1e+27 | K8: 1e+27
A9: SOEC | B9: KW | C9: 1e+27 | D9: 1e+27 | E9: 1e+27 | F9: 1e+27 | G9: 1e+27 | H9: 1e+27 | I9: 1e+27 | J9: 1e+27 | K9: 1e+27
A10: THP | B10: KW | C10: 1e+27 | D10: 1e+27 | E10: 1e+27 | F10: 1e+27 | G10: 1e+27 | H10: 1e+27 | I10: 1e+27 | J10: 1e+27 | K10: 1e+27
A11: BG | B11: KW | C11: 1e+27 | D11: 1e+27 | E11: 1e+27 | F11: 1e+27 | G11: 1e+27 | H11: 1e+27 | I11: 1e+27 | J11: 1e+27 | K11: 1e+27
A12: CG | B12: KW | C12: 2.3539334e+08 | D12: 2.3539334e+08 | E12: 2.3539334e+08 | F12: 2.3539334e+08 | G12: 2.3539334e+08 | H12: 2.3539334e+08 | I12: 2.6539334e+08 | J12: 2.6539334e+08 | K12: 2.6539334e+08
A13: SMR | B13: KW | C13: 77449437 | D13: =C13 -> 77449437 | E13: =D13 -> 77449437 | F13: =E13 -> 77449437 | G13: =F13 -> 77449437 | H13: =G13 -> 77449437 | I13: =H13 -> 77449437 | J13: =I13 -> 77449437 | K13: =J13 -> 77449437
A14: EXT | B14: KW | C14: 50737500 | D14: 45061875 | E14: 35686364 | F14: 21864773 | G14: 9230909.1 | H14: =G14*0.2 -> 1846181.8 | I14: 0 | J14: 0 | K14: 0

Sheet H2_P&C
A1: Mt H2 | B1: Coal | C1: Gas | D1: By-product | E1: Others(electrolysis…)
A2: Ammonia | B2: =7.9536*(11.067/10.8) -> 8.1502307 | C2: =2.6*(11.067/10.8) -> 2.6642778 | D2: =0.247*(11.067/10.8) -> 0.25310639 | E2: 0
A3: Methanol | B3: =6.2516*(9.198/8.2416) -> 6.9770696 | C3: =1.09*(9.198/8.2416) -> 1.2164895 | D3: =0.9*(9.198/8.2416) -> 1.0044409 | E3: 0
A4: Refining | B4: 0.94 | C4: 3.15 | D4: 4.73 | E4: 0
A5: Others(Heating, Waste…) | B5: 4.1748 | C5: 1.0724 | D5: 0.4628 | E5: 0.3

Sheet province_structure
A1: PROVINCE | B1: METH-CG | C1: METH-EXT | D1: METH-SMR | E1: AMM-CG | F1: AMM-EXT | G1: AMM-SMR | H1: Oil_Share | I1: ETH-MTO | J1: ETH-ESC | K1: ETH-NSC | L1: PRO-MTO | M1: PRO-PDH | N1: PRO-CC | O1: PRO-NSC | P1: BTX-CR | Q1: BTX-NSC | R1: METH_import
A2: Anhui | B2: 3.0325114 | C2: 0 | D2: 0 | E2: 3.4973967 | F2: 0 | G2: 0 | H2: =province_share!N2 -> 0 | I2: 0.35284662 | J2: 0 | K2: 0 | L2: 1.4000431 | M2: 0 | N2: 0.12500385 | O2: 0 | P2: 0 | Q2: 0 | R2: =3.27*(I2+L2)-SUM(B2:D2) -> 2.699438
A3: Beijing | B3: 0 | C3: 0 | D3: 0 | E3: 0 | F3: 0 | G3: 0 | H3: =province_share!N3 -> 0.021863155 | I3: 0 | J3: 0 | K3: 0.55867382 | L3: 0 | M3: 0 | N3: 0.2500077 | O3: 0.27933691 | P3: 0.27958969 | Q3: 0.22346953 | R3: 0
A4: Chongqing | B4: 0.64326 | C4: 0.707586 | D4: 1.511661 | E4: 0 | F4: 0 | G4: 1.4313189 | H4: =province_share!N4 -> 0 | I4: 0 | J4: 0 | K4: 0 | L4: 0 | M4: 0 | N4: 0 | O4: 0 | P4: 0 | Q4: 0 | R4: 0
A5: Fujian | B5: 0.21135686 | C5: 0 | D5: 0 | E5: 0 | F5: 0 | G5: 0 | H5: =province_share!N5 -> 0.076250522 | I5: 0 | J5: 0 | K5: 1.8230409 | L5: 0 | M5: 0.8250254 | N5: 0 | O5: 0.93752887 | P5: 2.6839604 | Q5: 0.85889538 | R5: 0
A6: Gansu | B6: 0.79029085 | C6: 0 | D6: 0 | E6: 0.90982098 | F6: 0 | G6: 0 | H6: =province_share!N6 -> 0.027577948 | I6: 0 | J6: 0.88211655 | K6: 0.70470515 | L6: 0 | M6: 0 | N6: 0 | O6: 0.35235257 | P6: 0 | Q6: 0.28188206 | R6: 0
A7: Guangdong | B7: 0 | C7: 0 | D7: 0 | E7: 0.37338754 | F7: 0 | G7: 0 | H7: =province_share!N7 -> 0.11524633 | I7: 0 | J7: 0 | K7: 2.4816879 | L7: 0 | M7: 1.3125404 | N7: 0.4125127 | O7: 1.850057 | P7: 1.8823543 | Q7: 1.0611758 | R7: 0
A8: Guangxi | B8: 0.91894285 | C8: 0 | D8: 0 | E8: 0.27381753 | F8: 0 | G8: 0 | H8: =province_share!N8 -> 0.032928894 | I8: 0 | J8: 0 | K8: 0.84143898 | L8: 0 | M8: 0 | N8: 0 | O8: 0.42071949 | P8: 0 | Q8: 0.33657559 | R8: 0
A9: Guizhou | B9: 1.3784143 | C9: 0 | D9: 0 | E9: 1.9914002 | F9: 0 | G9: 0 | H9: =province_share!N9 -> 0 | I9: 0.17642331 | J9: 0 | K9: 0 | L9: 0 | M9: 0 | N9: 0 | O9: 0 | P9: 0 | Q9: 0 | R9: 0
A10: Hainan | B10: 0 | C10: 0 | D10: 1.28652 | E10: 0 | F10: 0 | G10: 0.93346886 | H10: =province_share!N10 -> 0 | I10: 0 | J10: 0 | K10: 0 | L10: 0 | M10: 0 | N10: 0 | O10: 0 | P10: 1.3526985 | Q10: 0 | R10: 0
A11: Hebei | B11: 1.6449077 | C11: 1.87 | D11: 0.33081943 | E11: 2.0263338 | F11: 0 | G11: 0.44806505 | H11: =province_share!N11 -> 0.033687838 | I11: 0 | J11: 0 | K11: 0.86083243 | L11: 0 | M11: 0.62501925 | N11: 0 | O11: 0.43041622 | P11: 0 | Q11: 0.34433297 | R11: 0
A12: Heilongjiang | B12: 0.55871725 | C12: 0 | D12: 0.18378857 | E12: 0.59742007 | F12: 0 | G12: 0.8214526 | H12: =province_share!N12 -> 0.029144566 | I12: 0 | J12: 0 | K12: 0.70569324 | L12: 0 | M12: 0 | N12: 0.10000308 | O12: 0.47501463 | P12: 1.5152094 | Q12: 0.23139572 | R12: 0
A13: Henan | B13: 4.0892957 | C13: 0 | D13: 0.36757714 | E13: 4.5094201 | F13: 0 | G13: 0.47295756 | H13: =province_share!N13 -> 0.0048329079 | I13: 0.17642331 | J13: 0 | K13: 0.12349632 | L13: 0.20000616 | M13: 0 | N13: 0 | O13: 0.061748159 | P13: 0.30755298 | Q13: 0.049398527 | R13: 0
A14: Hubei | B14: 0.35838771 | C14: 0 | D14: 0 | E14: 2.8827749 | F14: 0 | G14: 0 | H14: =province_share!N14 -> 0.025315232 | I14: 0 | J14: 0 | K14: 0.64688547 | L14: 0 | M14: 0 | N14: 0.13750423 | O14: 0.32344274 | P14: 0 | Q14: 0.25875419 | R14: 0
... A16: Inner Mongolia | B16: 11.266239 | C16: 1.32 | D16: 1.4059826 | E16: 4.1254099 | F16: 0 | G16: 0.8214526 | H16: =province_share!N16 -> 0.010290279 | I16: 0.52926993 | J16: 0 | K16: 0.26294968 | L16: 1.7000523 | M16: 0 | N16: 0 | O16: 0.13147484 | P16: 0 | Q16: 0.10517987 | R16: 0
A17: Jiangsu | B17: 1.1532733 | C17: 0 | D17: 0 | E17: 3.3647878 | F17: 0 | G17: 0 | H17: =province_share!N17 -> 0.041623945 | I17: 0.57284649 | J17: 1.6642599 | K17: 0.4351775 | L17: 1.4011681 | M17: 1.5750485 | N17: 0 | O17: 0.98753041 | P17: 3.8361951 | Q17: 0.31225524 | R17: =3.27*(I17+L17)-SUM(B17:D17) -> 5.3017546
A18: Jiangxi | B18: 0 | C18: 0 | D18: 0 | E18: 1.2944102 | F18: 0 | G18: 0 | H18: =province_share!N18 -> 0 | I18: 0 | J18: 0 | K18: 0 | L18: 0 | M18: 0 | N18: 0 | O18: 0 | P18: 0.56944537 | Q18: 0 | R18: 0
A19: Jilin | B19: 0 | C19: 0 | D19: 0 | E19: 0.74677509 | F19: 0 | G19: 0 | H19: =province_share!N19 -> 0.018422274 | I19: 0.070569324 | J19: 0 | K19: 0.49986605 | L19: 0.22500693 | M19: 0 | N19: 0.2500077 | O19: 0.20625635 | P19: 0.69641361 | Q19: 0.19994642 | R19: =3.27*(I19+L19)-SUM(B19:D19) -> 0.96653435
A20: Liaoning | B20: 0.71677543 | C20: 0 | D20: 0.055136571 | E20: 0.80900635 | F20: 0 | G20: 0.77166759 | H20: =province_share!N20 -> 0.095406626 | I20: 0 | J20: 0 | K20: 2.5287341 | L20: 0 | M20: 0 | N20: 0.35001078 | O20: 0.50476554 | P20: 6.5436471 | Q20: 1.5102287 | R20: 0
A21: Ningxia | B21: 5.8996131 | C21: 0 | D21: 0 | E21: 0.68454383 | F21: 0.18491773 | G21: 1.7984833 | H21: =province_share!N21 -> 0.015980219 | I21: 0.73509713 | J21: 0 | K21: 0.36751132 | L21: 1.2375381 | M21: 0 | N21: 0.33751039 | O21: 0.24500754 | P21: 0.15776981 | Q21: 0.14700453 | R21: =3.27*(I21+L21)-SUM(B21:D21) -> 0.55090411
A22: Qinghai | B22: 0 | C22: 0 | D22: 1.8378857 | E22: 0 | F22: 0 | G22: 0.49785006 | H22: =province_share!N22 -> 0 | I22: 0 | J22: 0 | K22: 0 | L22: 0 | M22: 0 | N22: 0 | O22: 0 | P22: 0 | Q22: 0 | R22: 0
A23: Shaanxi | B23: 7.3055957 | C23: 0 | D23: 2.122758 | E23: 1.1948401 | F23: 0 | G23: 0.74677509 | H23: =province_share!N23 -> 0.020580559 | I23: 0.50574683 | J23: 0 | K23: 0.52589936 | L23: 0.7500231 | M23: 0 | N23: 0.4125127 | O23: 0.26294968 | P23: 0 | Q23: 0.21035974 | R23: 0
A24: Shandong | B24: 4.9806703 | C24: 1.2 | D24: 0.091894285 | E24: 6.3495287 | F24: 0.08455274 | G24: 0 | H24: =province_share!N24 -> 0.09887475 | I24: 0.17054253 | J24: 0.5880777 | K24: 0.47046216 | L24: 0.22500693 | M24: 2.6235808 | N24: 1.4700453 | O24: 0.2825087 | P24: 4.0891322 | Q24: 2.617689 | R24: 0
A25: Shanghai | B25: 0.73101904 | C25: 0 | D25: 0 | E25: 0 | F25: 0 | G25: 0 | H25: =province_share!N25 -> 0.066764298 | I25: 0 | J25: 0 | K25: 1.0526591 | L25: 0 | M25: 0 | N25: 0 | O25: 1.0975338 | P25: 2.1421857 | Q25: 0.74816 | R25: 0
A26: Shanxi | B26: 6.5796308 | C26: 3.05 | D26: 0 | E26: 4.8166993 | F26: 1.1802202 | G26: 0.49785006 | H26: =province_share!N26 -> 0.033496095 | I26: 0.17642331 | J26: 0 | K26: 0.85593279 | L26: 1.1250346 | M26: 0 | N26: 0.05000154 | O26: 0.4279664 | P26: 0.29125783 | Q26: 0.34237312 | R26: 0
A27: Sichuan | B27: 0 | C27: 0 | D27: 0.82704857 | E27: 0 | F27: 0.075361356 | G27: 3.5235338 | H27: =province_share!N27 -> 0.03587396 | I27: 0 | J27: 0.47046216 | K27: 0.8250254 | L27: 0 | M27: 0 | N27: 0.087502694 | O27: 0.55001694 | P27: 0.85172603 | Q27: 0.33001016 | R27: 0
A28: Tianjin | B28: 0.45947143 | C28: 0 | D28: 0 | E28: 0 | F28: 0 | G28: 0 | H28: =province_share!N28 -> 0.074671744 | I28: 0 | J28: 0.11761554 | K28: 0.88211655 | L28: 0 | M28: 0.75002309 | N28: 0 | O28: 0.44105828 | P28: 0.30627777 | Q28: 1.5840302 | R28: 0
A29: Xinjiang | B29: 3.3081943 | C29: 0 | D29: 0.18378857 | E29: 2.1185032 | F29: 0 | G29: 1.739986 | H29: =province_share!N29 -> 0.037858401 | I29: 0 | J29: 0.35284662 | K29: 0.77626257 | L29: 0 | M29: 0 | N29: 0 | O29: 0.80002463 | P29: 1.2689339 | Q29: 0.21035974 | R29: 0
A30: Yunnan | B30: 0.257304 | C30: 0 | D30: 0 | E30: 1.6304589 | F30: 0 | G30: 0 | H30: =province_share!N30 -> 0.0063335303 | I30: 0 | J30: 0 | K30: 0.16184204 | L30: 0 | M30: 0 | N30: 0 | O30: 0.080921019 | P30: 0 | Q30: 0.064736815 | R30: 0
A31: Zhejiang | B31: 0.33081943 | C31: 0 | D31: 0.009189429 | E31: 1.1736815 | F31: 0 | G31: 0.55385819 | H31: =province_share!N31 -> 0.076975928 | I31: 0.29403885 | J31: 1.6466176 | K31: 1.9994642 | L31: 0.98753041 | M31: 6.9127129 | N31: 1.5375473 | O31: 0.11250346 | P31: 11.799925 | Q31: 1.4705902 | R31: =3.27*(I31+L31)-SUM(B31:D31) -> 3.8507226

Sheet province_share
A1: PROVINCE | B1: AMM_Share | C1: METH_Share | D1: ETH_Share | E1: PRO_Share | F1: BTX_Share | G1: Oil_Share | H1: METH_Import_Share | I1: AMM_Supply_Share | J1: METH_Supply_Share | K1: ETH_Supply_Share | L1: PRO_Supply_Share | M1: BTX_Supply_Share | N1: Oil_Supply_Share
A2: Anhui | B2: =I2 -> 0.056113151 | C2: =J2 -> 0.040342417 | D2: =K2 -> 0.011811722 | E2: =L2 -> 0.037510381 | F2: =M2 -> 0 | G2: =N2 -> 0 | H2: =province_structure!R2/SUM(province_structure!R$2:R$31) -> 0.20191238 | I2: 0.056113151 | J2: 0.040342417 | K2: 0.011811722 | L2: 0.037510381 | M2: 0 | N2: 0
A3: Beijing | B3: =I3 -> 0 | C3: =J3 -> 0 | D3: =K3 -> 0.018701893 | E3: =L3 -> 0.013019873 | F3: =M3 -> 0.0093033211 | G3: =N3 -> 0.021863155 | H3: =province_structure!R3/SUM(province_structure!R$2:R$31) -> 0 | I3: 0 | J3: 0 | K3: 0.018701893 | L3: 0.013019873 | M3: 0.0093033211 | N3: 0.021863155
A4: Chongqing | B4: =I4 -> 0.022964457 | C4: =J4 -> 0.038080796 | D4: =K4 -> 0 | E4: =L4 -> 0 | F4: =M4 -> 0 | G4: =N4 -> 0 | H4: =province_structure!R4/SUM(province_structure!R$2:R$31) -> 0 | I4: 0.022964457 | J4: 0.038080796 | K4: 0 | L4: 0 | M4: 0 | N4: 0
A5: Fujian | B5: =I5 -> 0 | C5: =J5 -> 0.0028117442 | D5: =K5 -> 0.061027231 | E5: =L5 -> 0.043352161 | F5: =M5 -> 0.065519772 | G5: =N5 -> 0.076250522 | H5: =province_structure!R5/SUM(province_structure!R$2:R$31) -> 0 | I5: 0 | J5: 0.0028117442 | K5: 0.061027231 | L5: 0.043352161 | M5: 0.065519772 | N5: 0.076250522
A6: Gansu | B6: =I6 -> 0.014597407 | C6: =J6 -> 0.010513478 | D6: =K6 -> 0.053119672 | E6: =L6 -> 0.0086665391 | F6: =M6 -> 0.0052129833 | G6: =N6 -> 0.027577948 | H6: =province_structure!R6/SUM(province_structure!R$2:R$31) -> 0 | I6: 0.014597407 | J6: 0.010513478 | K6: 0.053119672 | L6: 0.0086665391 | M6: 0.0052129833 | N6: 0.027577948
A7: Guangdong | B7: =I7 -> 0.0059907278 | C7: =J7 -> 0 | D7: =K7 -> 0.083075779 | E7: =L7 -> 0.087934171 | F7: =M7 -> 0.054436149 | G7: =N7 -> 0.11524633 | H7: =province_structure!R7/SUM(province_structure!R$2:R$31) -> 0 | I7: 0.0059907278 | J7: 0 | K7: 0.083075779 | L7: 0.087934171 | M7: 0.054436149 | N7: 0.11524633
A8: Guangxi | B8: =I8 -> 0.0043932004 | C8: =J8 -> 0.012224975 | D8: =K8 -> 0.028167603 | E8: =L8 -> 0.010348106 | F8: =M8 -> 0.0062244577 | G8: =N8 -> 0.032928894 | H8: =province_structure!R8/SUM(province_structure!R$2:R$31) -> 0 | I8: 0.0043932004 | J8: 0.012224975 | K8: 0.028167603 | L8: 0.010348106 | M8: 0.0062244577 | N8: 0.032928894
A9: Guizhou | B9: =I9 -> 0.031950548 | C9: =J9 -> 0.018337462 | D9: =K9 -> 0.0059058611 | E9: =L9 -> 0 | F9: =M9 -> 0 | G9: =N9 -> 0 | H9: =province_structure!R9/SUM(province_structure!R$2:R$31) -> 0 | I9: 0.031950548 | J9: 0.018337462 | K9: 0.0059058611 | L9: 0 | M9: 0 | N9: 0
A10: Hainan | B10: =I10 -> 0.01497682 | C10: =J10 -> 0.017114965 | D10: =K10 -> 0 | E10: =L10 -> 0 | F10: =M10 -> 0.025016118 | G10: =N10 -> 0 | H10: =province_structure!R10/SUM(province_structure!R$2:R$31) -> 0 | I10: 0.01497682 | J10: 0.017114965 | K10: 0 | L10: 0 | M10: 0.025016118 | N10: 0
A11: Hebei | B11: =I11 -> 0.039699905 | C11: =J11 -> 0.051160872 | D11: =K11 -> 0.028816808 | E11: =L11 -> 0.025959716 | F11: =M11 -> 0.0063679188 | G11: =N11 -> 0.033687838 | H11: =province_structure!R11/SUM(province_structure!R$2:R$31) -> 0 | I11: 0.039699905 | J11: 0.051160872 | K11: 0.028816808 | L11: 0.025959716 | M11: 0.0063679188 | N11: 0.033687838
A12: Heilongjiang | B12: =I12 -> 0.022764766 | C12: =J12 -> 0.0098777796 | D12: =K12 -> 0.023623444 | E12: =L12 -> 0.014143258 | F12: =M12 -> 0.032300826 | G12: =N12 -> 0.029144566 | H12: =province_structure!R12/SUM(province_structure!R$2:R$31) -> 0 | I12: 0.022764766 | J12: 0.0098777796 | K12: 0.023623444 | L12: 0.014143258 | M12: 0.032300826 | N12: 0.029144566
A13: Henan | B13: =I13 -> 0.079938576 | C13: =J13 -> 0.059291128 | D13: =K13 -> 0.010039964 | E13: =L13 -> 0.0064381651 | F13: =M13 -> 0.0066012795 | G13: =N13 -> 0.0048329079 | H13: =province_structure!R13/SUM(province_structure!R$2:R$31) -> 0 | I13: 0.079938576 | J13: 0.059291128 | K13: 0.010039964 | L13: 0.0064381651 | M13: 0.0066012795 | N13: 0.0048329079
... A31: Zhejiang | B31: =I31 -> 0.027717101 | C31: =J31 -> 0.0045232407 | D31: =K31 -> 0.13189756 | E31: =L31 -> 0.23490107 | F31: =M31 -> 0.24541816 | G31: =N31 -> 0.076975928 | H31: =province_structure!R31/SUM(province_structure!R$2:R$31) -> 0.28802609 | I31: 0.027717101 | J31: 0.0045232407 | K31: 0.13189756 | L31: 0.23490107 | M31: 0.24541816 | N31: 0.076975928

Sheet CCS-cost_v1
A1: scenario | B1: unit | C1: 2020 | D1: 2025 | E1: 2030 | F1: 2035 | G1: 2040 | H1: 2045 | I1: 2050 | J1: 2055 | K1: 2060
A2: S2 | B2: RMB/t | C2: 616 | D2: 583.8 | E2: 551.6 | F2: 533.05 | G2: 514.5 | H2: 500.7415 | I2: 486.983 | J2: 457.3415 | K2: 427.7

Sheet CCS_cost
A1: Province | B1: 2020 | C1: 2030 | D1: 2040 | E1: 2050 | F1: 2060
A2: Anhui | B2: 440.03475 | C2: 381.142 | D2: 342.24925 | E2: 322.80287 | F2: 293.3565
A3: Beijing | B3: 394.27107 | C3: 340.46317 | D3: 306.65527 | E3: 289.75133 | F3: 262.84738
A4: Chongqing | B4: 401.51938 | C4: 346.90612 | D4: 312.29285 | E4: 294.98622 | F4: 267.67959
A5: Fujian | B5: 915.47724 | C5: 803.75755 | D5: 712.03786 | E5: 666.17801 | F5: 610.31816
A6: Gansu | B6: 470.8791 | C6: 408.5592 | D6: 366.2393 | E6: 345.07935 | F6: 313.9194
A7: Guangdong | B7: 1002.4127 | C7: 881.03351 | D7: 779.65432 | E7: 728.96472 | F7: 668.27513
A8: Guangxi | B8: 1010.8025 | C8: 888.49108 | D8: 786.1797 | E8: 735.02401 | F8: 673.86831
A9: Guizhou | B9: 488.95958 | C9: 424.63074 | D9: 380.3019 | E9: 358.13748 | F9: 325.97306
A10: Hainan | B10: 1005 | C10: 870 | D10: 795 | E10: 737.5 | F10: 670
A11: Hebei | B11: 424.94598 | C11: 367.72976 | D11: 330.51354 | E11: 311.90543 | F11: 283.29732
A12: Heilongjiang | B12: 398.3022 | C12: 344.0464 | D12: 309.7906 | E12: 292.6627 | F12: 265.5348
... A31: Zhejiang | B31: 644.63813 | C31: 563.01168 | D31: 501.38522 | E31: 470.57199 | F31: 429.75876

Sheet Demand
A1: scenario | B1: downstream | C1: unit | D1: 2020 | E1: 2025 | F1: 2030 | G1: 2035 | H1: 2040 | I1: 2045 | J1: 2050 | K1: 2055 | L1: 2060
A2: basic | B2: AMM | C2: Mt | D2: 60 | E2: 56.5 | F2: 58.5 | G2: 58.625 | H2: 61.75 | I2: 67.875 | J2: 80.5 | K2: 95 | L2: 108
A3: basic | B3: METH | C3: Mt | D3: 69.9993 | E3: 77.66 | F3: 87.75 | G3: 95.55 | H3: 109.48 | I3: 123.69 | J3: 138.18 | K3: 152.145 | L3: 166.25
A4: basic | B4: Oil | C4: Mt | D4: 700 | E4: 735 | F4: 770 | G4: 722.5 | H4: 675 | I4: 627.5 | J4: 580 | K4: 570 | L4: 560
A5: more | B5: AMM | C5: Mt | D5: 60 | E5: 56.5 | F5: 60.5 | G5: 67.625 | H5: 77.9875 | I5: 90.3625 | J5: 103 | K5: 117.5 | L5: 132
A6: more | B6: METH | C6: Mt | D6: 69.9993 | E6: 78.1 | F6: 86.85 | G6: 93.275 | H6: 103.04 | I6: 119.04 | J6: 142.88 | K6: 169.155 | L6: 198.55
A7: more | B7: Oil | C7: Mt | D7: 700 | E7: 735 | F7: 768.0529 | G7: 714.62734 | H7: 663.06461 | I7: 610.99329 | J7: 560.52901 | K7: 545.78615 | L7: 531.21332
A8: less | B8: AMM | C8: Mt | D8: 60 | E8: 56.5 | F8: 54.5 | G8: 54.625 | H8: 55.75 | I8: 57.875 | J8: 67 | K8: 81 | L8: 96
A9: less | B9: METH | C9: Mt | D9: 69.9993 | E9: 77.66 | F9: 87.75 | G9: 94.64 | H9: 103.96 | I9: 110.67 | J9: 120.32 | K9: 133.245 | L9: 140
A10: less | B10: Oil | C10: Mt | D10: 700 | E10: 735 | F10: 770 | G10: 717.5 | H10: 660 | I10: 605 | J10: 550 | K10: 535 | L10: 520

Sheet Carbon-target
A1: scenario | B1: unit | C1: 2020 | D1: 2025 | E1: 2030 | F1: 2035 | G1: 2040 | H1: 2045 | I1: 2050 | J1: 2055 | K1: 2060
A2: M-not CN | B2: kg | C2: 550308000000 | D2: 6.4168629e+11 | E2: =F2*1.03 -> 695059640550 | F2: =G2*1.09 -> 674815185000 | G2: =H2*1.2 -> 619096500000 | H2: =I2*1.5 -> 515913750000 | I2: =J2*2.5 -> 343942500000 | J2: =C2/4 -> 137577000000 | K2: =C2*0.1 -> 55030800000
A3: H-CN 2060 | B3: kg | C3: 1100308000000 | D3: 1.1553644e+12 | E3: 1.1553644e+12 | F3: 1.039828e+12 | G3: 8.3186239e+11 | H3: 5.8230367e+11 | I3: 275077000000 | J3: 104529260000 | K3: 0
A4: L：BAU | B4: kg | C4: =C3 -> 1100308000000 | D4: =$C4*10000 -> 1.100308e+16 | E4: =$C4*10000 -> 1.100308e+16 | F4: =$C4*10000 -> 1.100308e+16 | G4: =$C4*10000 -> 1.100308e+16 | H4: =$C4*10000 -> 1.100308e+16 | I4: =$C4*10000 -> 1.100308e+16 | J4: =$C4*10000 -> 1.100308e+16 | K4: =$C4*10000 -> 1.100308e+16

Sheet Hydro-POT
A1: PROVINCE_ID | B1: PROVINCE | C1: Hydro_2023 | D1: Nuclear_2023
A2: AH | B2: Anhui | C2: 6220 | D2: 0
A3: BJ | B3: Beijing | C3: 20 | D3: 0
A4: CQ | B4: Chongqing | C4: 12505.751 | D4: 0
A5: FJ | B5: Fujian | C5: 12678.001 | D5: 1101
A6: GS | B6: Gansu | C6: 27292.634 | D6: 0
A7: GD | B7: Guangdong | C7: 27561.404 | D7: 1614
A8: GX | B8: Guangxi | C8: 35767.13 | D8: 336
A9: GZ | B9: Guizhou | C9: 20973.622 | D9: 0
A10: HI | B10: Hainan | C10: 2420 | D10: 130
A11: HE | B11: Hebei | C11: 12620 | D11: 0
A12: HL | B12: Heilongjiang | C12: 13367.129 | D12: 0
A13: HA | B13: Henan | C13: 13192.21 | D13: 0
... A31: ZJ | B31: Zhejiang | C31: 21515 | D31: 917

Sheet Bio-POT
A1: PROVINCE | B1: BAU | C1: MAR II | D1: MAR I | E1: MAR I+II
A2: Anhui | B2: 0.030891151 | C2: 0.19053867 | D2: 0.10115165 | E2: 0.24710556
A3: Beijing | B3: 0.00094364288 | C3: 0.021913423 | D3: 0.012928927 | E3: 0.032814504
A4: Chongqing | B4: 0.0077417136 | C4: 0.091099334 | D4: 0.096608486 | E4: 0.14924932
A5: Fujian | B5: 0.017121755 | C5: 0.096452171 | D5: 0.15888771 | E5: 0.2184439
A6: Gansu | B6: 0.0080608704 | C6: 0.12479847 | D6: 0.14257925 | E6: 0.22604852
A7: Guangdong | B7: 0.016870087 | C7: 0.16383892 | D7: 0.11806326 | E7: 0.24084774
A8: Guangxi | B8: 0.034964398 | C8: 0.17250671 | D8: 0.42344967 | E8: 0.49894975
A9: Guizhou | B9: 0.011532547 | C9: 0.16737673 | D9: 0.43064087 | E9: 0.49775497
A10: Hainan | B10: 0.004674093 | C10: 0.02155433 | D10: 0.020768925 | E10: 0.033889941
A11: Hebei | B11: 0.031528073 | C11: 0.19884313 | D11: 0.10839984 | E11: 0.2634832
A12: Heilongjiang | B12: 0.047018501 | C12: 0.070997266 | D12: 0.06451189 | E12: 0.084361963
A13: Henan | B13: 0.045834398 | C13: 0.23468111 | D13: 0.082669368 | E13: 0.2626615
... A31: Zhejiang | B31: 0.0096462984 | C31: 0.10922159 | D31: 0.058335655 | E31: 0.14809214

Sheet Industry_CO2_POT
A1: level | B1: unit | C1: 2020 | D1: 2025 | E1: 2030 | F1: 2035 | G1: 2040 | H1: 2045 | I1: 2050 | J1: 2055 | K1: 2060
A2: low | B2: kg | C2: 0 | D2: 0 | E2: 0 | F2: 0 | G2: 0 | H2: 0 | I2: 0 | J2: 0 | K2: 0
A3: medium | B3: kg | C3: 0 | D3: 0 | E3: 0 | F3: 0 | G3: 0 | H3: 0 | I3: 0 | J3: 0 | K3: 0
A4: high | B4: kg | C4: 0 | D4: 0 | E4: 0 | F4: 0 | G4: 0 | H4: 0 | I4: 0 | J4: 0 | K4: 0

Sheet Metals_g KW h
B1: Wind-Al | C1: Wind-Nd | D1: Solar-Al | E1: Solar-Sb | F1: AE-Ni | G1: SOEC-Ni | H1: SOEC-Sc | I1: SOEC-La | J1: SOEC-Y | K1: PEM-Ti | L1: PEM-Pt | M1: PEM-Ir | N1: Energy_stroage-Li
A2: 2020 | B2: 1690 | C2: 43.83 | D2: 6503.52 | E2: 76.92 | F2: 950 | G2: 7.1 | H2: 23 | I2: 20 | J2: 5 | K2: 528 | L2: 0.33 | M2: 0.667 | N2: 110
A3: 2021 | B3: 1612.575 | C3: 42.742438 | D3: 6195.1368 | E3: 75.9737 | F3: 915 | G3: 6.895 | H3: 21.9075 | I3: 19.5 | J3: 4.875 | K3: 504.1 | L3: 0.31535 | M3: 0.63615 | N3: 110
A4: 2022 | B4: 1536.3 | C4: 41.67025 | D4: 5894.1112 | E4: 75.0008 | F4: 880 | G4: 6.69 | H4: 20.815 | I4: 19 | J4: 4.75 | K4: 480.2 | L4: 0.3007 | M4: 0.6053 | N4: 110
A5: 2023 | B5: 1461.175 | C5: 40.613438 | D5: 5600.4432 | E5: 74.0013 | F5: 845 | G5: 6.485 | H5: 19.7225 | I5: 18.5 | J5: 4.625 | K5: 456.3 | L5: 0.28605 | M5: 0.57445 | N5: 110
A6: 2024 | B6: 1387.2 | C6: 39.572 | D6: 5314.1328 | E6: 72.9752 | F6: 810 | G6: 6.28 | H6: 18.63 | I6: 18 | J6: 4.5 | K6: 432.4 | L6: 0.2714 | M6: 0.5436 | N6: 110
A7: 2025 | B7: 1314.375 | C7: 38.545938 | D7: 5035.18 | E7: 71.9225 | F7: 775 | G7: 6.075 | H7: 17.5375 | I7: 17.5 | J7: 4.375 | K7: 408.5 | L7: 0.25675 | M7: 0.51275 | N7: 110
A8: 2026 | B8: 1242.7 | C8: 37.53525 | D8: 4763.5848 | E8: 70.8432 | F8: 740 | G8: 5.87 | H8: 16.445 | I8: 17 | J8: 4.25 | K8: 384.6 | L8: 0.2421 | M8: 0.4819 | N8: 110
A9: 2027 | B9: 1172.175 | C9: 36.539938 | D9: 4499.3472 | E9: 69.7373 | F9: 705 | G9: 5.665 | H9: 15.3525 | I9: 16.5 | J9: 4.125 | K9: 360.7 | L9: 0.22745 | M9: 0.45105 | N9: 110
A10: 2028 | B10: 1102.8 | C10: 35.56 | D10: 4242.4672 | E10: 68.6048 | F10: 670 | G10: 5.46 | H10: 14.26 | I10: 16 | J10: 4 | K10: 336.8 | L10: 0.2128 | M10: 0.4202 | N10: 110
A11: 2029 | B11: 1034.575 | C11: 34.595438 | D11: 3992.9448 | E11: 67.4457 | F11: 635 | G11: 5.255 | H11: 13.1675 | I11: 15.5 | J11: 3.875 | K11: 312.9 | L11: 0.19815 | M11: 0.38935 | N11: 110
A12: 2030 | B12: 967.5 | C12: 33.64625 | D12: 3750.78 | E12: 66.26 | F12: 600 | G12: 5.05 | H12: 12.075 | I12: 15 | J12: 3.75 | K12: 289 | L12: 0.1835 | M12: 0.3585 | N12: 110
A13: 2031 | B13: 924.245 | C13: 32.905212 | D13: 3655.37 | E13: 65.35636 | F13: 579 | G13: 4.927 | H13: 11.4195 | I13: 14.7 | J13: 3.675 | K13: 274.66 | L13: 0.17471 | M13: 0.33999 | N13: 110
... A42: 2060 | B42: 290 | C42: 17.5 | D42: 2423.2 | E42: 50 | F42: 250 | G42: 3 | H42: 1.15 | I42: 10 | J42: 2.5 | K42: 50 | L42: 0.037 | M42: 0.05 | N42: 110

Sheet CDR-cost
A1: level | B1: unit | C1: 2020 | D1: 2025 | E1: 2030 | F1: 2035 | G1: 2040 | H1: 2045 | I1: 2050 | J1: 2055 | K1: 2060
A2: DAC-M | B2: RMB/t | C2: 2703.5 | D2: 2315.9 | E2: 1928.3 | F2: 1756.02 | G2: 1583.74 | H2: 1498.188 | I2: 1412.636 | J2: 1372.568 | K2: 1332.5
A3: DAC-H | B3: RMB/t | C3: 2703.5 | D3: 2605.3875 | E3: 2410.375 | F3: 2107.224 | G3: 1900.488 | H3: 1797.8256 | I3: 1695.1632 | J3: 1647.0816 | K3: 1599
A4: DAC-L | B4: RMB/t | C4: 2703.5 | D4: 2026.4125 | E4: 1446.225 | F4: 1404.816 | G4: 1266.992 | H4: 1198.5504 | I4: 1130.1088 | J4: 1098.0544 | K4: 1066

Sheet Trans_cost
A1: DIS | B1: unit | C1: type | D1: AMM | E1: METH | F1: H2
A2: 500 | B2: USD/t.km | C2: pipeline | D2: =180/500 -> 0.36 | E2: =220/500 -> 0.44 | F2: =1850/500 -> 3.7
A3: 1000 | B3: USD/t.km | C3: pipeline | D3: =190/1000 -> 0.19 | E3: =230/1000 -> 0.23 | F3: =2200/1000 -> 2.2
A4: 1500 | B4: USD/t.km | C4: pipeline | D4: =220/1500 -> 0.14666667 | E4: =250/1500 -> 0.16666667 | F4: =2300/1500 -> 1.5333333
A5: 2000 | B5: USD/t.km | C5: pipeline | D5: =230/2000 -> 0.115 | E5: =260/2000 -> 0.13 | F5: =2500/2000 -> 1.25

Sheet Demand_v2
A1: chemical | B1: downstream | C1: unit | D1: 2020 | E1: 2025 | F1: 2030 | G1: 2035 | H1: 2040 | I1: 2045 | J1: 2050 | K1: 2055 | L1: 2060
A2: AMM | B2: Agriculture | C2: Mt | D2: 42 | E2: 35 | F2: 31 | G2: 28 | H2: 27 | I2: 26 | J2: 25.5 | K2: 25 | L2: 25
A3: AMM | B3: Industry | C3: Mt | D3: 20.5 | E3: 21.5 | F3: 24.5 | G3: 24.625 | H3: 24.75 | I3: 24.875 | J3: 25 | K3: 25 | L3: 25
A4: AMM | B4: Energy carrier | C4: Mt | D4: 0 | E4: 0 | F4: 3 | G4: 6 | H4: 10 | I4: 17 | J4: 30 | K4: 45 | L4: 58
A5: METH | B5: MTO_domestic | C5: Mt | D5: 33.548 | E5: 35.5275 | F5: 45.25 | G5: 51.6 | H5: 62.86 | I5: 74.68 | J5: 87.06 | K5: 100 | L5: 110
A6: METH | B6: Traditional industry | C6: Mt | D6: 26 | E6: 25.25 | F6: 24.5 | G6: 24 | H6: 24 | I6: 23 | J6: 22 | K6: 21 | L6: 20
A7: METH | B7: Energy carrier | C7: Mt | D7: 14 | E7: 16 | F7: 18 | G7: 21 | H7: 25 | I7: 30 | J7: 35 | K7: 40 | L7: 45
A8: METH | B8: MTO_import | C8: Mt | D8: 13.452 | E8: 11.4725 | F8: 9.75 | G8: 8.4 | H8: 7.14 | I8: 5.32 | J8: 2.94 | K8: 0 | L8: 0
A9: Oil | B9: Transport | C9: Mt | D9: 329 | E9: 359.5 | F9: 390 | G9: 340 | H9: 290 | I9: 240 | J9: 190 | K9: 180 | L9: 170
A10: Oil | B10: HVC | C10: Mt | D10: 161 | E10: 170.5 | F10: 180 | G10: 190 | H10: 200 | I10: 215 | J10: 230 | K10: 245 | L10: 260
A11: Oil | B11: Traditional industry | C11: Mt | D11: 210 | E11: 205 | F11: 200 | G11: 192.5 | H11: 185 | I11: 177.5 | J11: 170 | K11: 165 | L11: 160
A12: ETH | B12: Ethylene | C12: Mt | D12: 29.87 | E12: 32.265166 | F12: 35.064783 | G12: 38.775342 | H12: 42.523006 | I12: 46.270671 | J12: 49.072143 | K12: 53.63613 | L12: 58.367093
... A14: BTX | B14: BTX | C14: Mt | D14: 54.07 | E14: 54.397443 | F14: 54.405839 | G14: 54.237919 | H14: 54.556966 | I14: 54.876012 | J14: 54.842429 | K14: 51.836674 | L14: 51.517627

Sheet HVC_para
A1: process | B1: var | C1: unit | D1: value
A2: NSC | B2: CAP | C2: USD/t HVC.年 | D2: 111.51
A3: NSC | B3: OM | C3: USD/t HVC | D3: 63
A4: NSC | B4: out/in-2020 | C4: t HVC/t naphtha | D4: 0.98
A5: NSC | B5: out/in-2030 | C5: t HVC/t naphtha | D5: 0.98
A6: NSC | B6: out/in-2040 | C6: t HVC/t naphtha | D6: 0.98
A7: NSC | B7: out/in-2050 | C7: t HVC/t naphtha | D7: 0.98
A8: NSC | B8: out/in-2060 | C8: t HVC/t naphtha | D8: 0.98
A9: NSC | B9: output-E | C9: t E/t HVC | D9: 25-35%
A10: NSC | B10: output-P | C10: t P/t HVC | D10: 13-20%
A11: NSC | B11: output-BTX | C11: t BTX/t HVC | D11: 10-15%
A12: NSC | B12: output-sum | C12: t EPBTX/t HVC | D12: 0.6
A13: NSC | B13: FS_cost-2020 | C13: USD/t naphtha | D13: 650
A14: NSC | B14: FS_cost-2030 | C14: USD/t naphtha | D14: 900
A15: NSC | B15: FS_cost-2040 | C15: USD/t naphtha | D15: 1000
A16: NSC | B16: FS_cost-2050 | C16: USD/t naphtha | D16: 1100
A17: NSC | B17: FS_cost-2060 | C17: USD/t naphtha | D17: 1100
A18: NSC | B18: CF | C18: tCO2/tEorPorBTX | D18: 0.227
A19: CC | B19: CAP | C19: USD/t P | D19: 60.81
A20: CC | B20: OM | C20: USD/t P | D20: 34.32
A21: CC | B21: out/in-2020 | C21: t P/t heavy oil | D21: 0.08
A22: CC | B22: out/in-2030 | C22: t P/t heavy oil | D22: 0.08
A23: CC | B23: out/in-2040 | C23: t P/t heavy oil | D23: 0.08
... A73: MTO | B73: OM | C73: USD/t E | D73: 22
A74: MTO | B74: out/in-2020 | C74: t E/t M | D74: =1/3.27 -> 0.3058104
A75: MTO | B75: out/in-2030 | C75: t E/t M | D75: =1/3.27 -> 0.3058104
A76: MTO | B76: out/in-2040 | C76: t E/t M | D76: =1/3.27 -> 0.3058104
A77: MTO | B77: out/in-2050 | C77: t E/t M | D77: =1/3.27 -> 0.3058104
A78: MTO | B78: out/in-2060 | C78: t E/t M | D78: =1/3.27 -> 0.3058104
A79: MTO | B79: FS_cost-2020 | C79: USD/t M | D79: 270
A80: MTO | B80: FS_cost-2030 | C80: USD/t M | D80: 320
A81: MTO | B81: FS_cost-2040 | C81: USD/t M | D81: 330
A82: MTO | B82: FS_cost-2050 | C82: USD/t M | D82: 340
A83: MTO | B83: FS_cost-2060 | C83: USD/t M | D83: 345
A84: MTO | B84: CF | C84: t CO2/t EorP | D84: 0.051
A85: Embodied CF | B85: METH | C85: t CO2/t | D85: 1.375
A86: Embodied CF | B86: ETH | C86: t CO3/t | D86: 3.1429
A87: Embodied CF | B87: PRO | C87: t CO4/t | D87: 3.1429
A88: Embodied CF | B88: BTX | C88: t CO5/t | D88: 3.35

Sheet HVC_CCS_ratio
A1: HVCs | B1: unit | C1: 2020 | D1: 2030 | E1: 2040 | F1: 2050 | G1: 2060
A2: EOL-CCS ratio | B2: 1 | C2: 0.185 | D2: 0.25 | E2: 0.35 | F2: 0.55 | G2: 0.65

Sheet W&S_POT
A1: PROVINCE | B1: Solar_Distributed | C1: Solar_Utility | D1: Wind_Offshore | E1: Wind_Onshore | F1: Solar | G1: Wind
A2: Anhui | B2: 158.64244 | C2: 31.21216 | D2: 0 | E2: 11.258544 | F2: 189.8546 | G2: 11.258544
A3: Beijing | B3: 37.10404 | C3: 4.9040396 | D3: 0 | E3: 2.5232351 | F3: 42.008079 | G3: 2.5232351
A4: Chongqing | B4: 17.343324 | C4: 19.588519 | D4: 0 | E4: 2.6477392 | F4: 36.931843 | G4: 2.6477392
A5: Fujian | B5: 47.427871 | C5: 101.86643 | D5: 68.815764 | E5: 7.6189901 | F5: 149.2943 | G5: 76.434755
A6: Gansu | B6: 12.033865 | C6: 2400.0003 | D6: 0 | E6: 159.23316 | F6: 2412.0341 | G6: 159.23316
A7: Guangdong | B7: 121.5255 | C7: 186.84069 | D7: 176.6652 | E7: 33.849079 | F7: 308.36619 | G7: 210.51428
A8: Guangxi | B8: 65.907971 | C8: 272.51689 | D8: 49.068764 | E8: 108.15805 | F8: 338.42486 | G8: 157.22682
A9: Guizhou | B9: 9.6388186 | C9: 105.44705 | D9: 0 | E9: 42.478371 | F9: 115.08587 | G9: 42.478371
